<?xml version="1.0" encoding="utf-8"?>
<!-- =================================================================================== -->
<!-- |    This document was autogenerated by xacro from car_arm_model.urdf.xacro       | -->
<!-- |    EDITING THIS FILE BY HAND IS NOT RECOMMENDED                                 | -->
<!-- =================================================================================== -->
<robot name="robot">
  <!-- rviz color -->
  <material name="blue">
    <color rgba="0 0 1 1"/>
  </material>
  <material name="black">
    <color rgba="0 0 0 1"/>
  </material>
  <material name="white">
    <color rgba="1 1 1 1"/>
  </material>
  <material name="chain">
    <color rgba="0.4 0 0.8 1"/>
  </material>
  <!-- common stuff -->
  <!--xacro:include filename="$(find gazebo_example)/urdf/common.gazebo.xacro" /-->
  <!--
  Author: Kelsey Hawkins
  Contributers: Jimmy Da Silva, Ajit Krisshna N L, Muhammad Asif Rana
-->
  <!-- measured from model -->
  <link name="/mbx/base_link">
    <visual>
      <geometry>
        <mesh filename="package://gazebo_example/meshes/ur10/visual/base.dae"/>
      </geometry>
      <material name="LightGrey">
        <color rgba="0.7 0.7 0.7 1.0"/>
      </material>
    </visual>
    <collision>
      <geometry>
        <mesh filename="package://gazebo_example/meshes/ur10/collision/base.stl"/>
      </geometry>
    </collision>
    <inertial>
      <mass value="4.0"/>
      <origin rpy="0 0 0" xyz="0.0 0.0 0.0"/>
      <inertia ixx="0.0061063308908" ixy="0.0" ixz="0.0" iyy="0.0061063308908" iyz="0.0" izz="0.01125"/>
    </inertial>
  </link>
  <joint name="/mbx/shoulder_pan_joint" type="revolute">
    <parent link="/mbx/base_link"/>
    <child link="/mbx/shoulder_link"/>
    <origin rpy="0.0 0.0 0.0" xyz="0.0 0.0 0.1273"/>
    <axis xyz="0 0 1"/>
    <limit effort="330.0" lower="-6.28318530718" upper="6.28318530718" velocity="2.16"/>
    <dynamics damping="0.0" friction="0.0"/>
  </joint>
  <link name="/mbx/shoulder_link">
    <visual>
      <geometry>
        <mesh filename="package://gazebo_example/meshes/ur10/visual/shoulder.dae"/>
      </geometry>
      <material name="LightGrey">
        <color rgba="0.7 0.7 0.7 1.0"/>
      </material>
    </visual>
    <collision>
      <geometry>
        <mesh filename="package://gazebo_example/meshes/ur10/collision/shoulder.stl"/>
      </geometry>
    </collision>
    <inertial>
      <mass value="7.778"/>
      <origin rpy="0 0 0" xyz="0.0 0.0 0.0"/>
      <inertia ixx="0.0314743125769" ixy="0.0" ixz="0.0" iyy="0.0314743125769" iyz="0.0" izz="0.021875625"/>
    </inertial>
  </link>
  <joint name="/mbx/shoulder_lift_joint" type="revolute">
    <parent link="/mbx/shoulder_link"/>
    <child link="/mbx/upper_arm_link"/>
    <origin rpy="0.0 1.57079632679 0.0" xyz="0.0 0.220941 0.0"/>
    <axis xyz="0 1 0"/>
    <limit effort="330.0" lower="-6.28318530718" upper="6.28318530718" velocity="2.16"/>
    <dynamics damping="0.0" friction="0.0"/>
  </joint>
  <link name="/mbx/upper_arm_link">
    <visual>
      <geometry>
        <mesh filename="package://gazebo_example/meshes/ur10/visual/upperarm.dae"/>
      </geometry>
      <material name="LightGrey">
        <color rgba="0.7 0.7 0.7 1.0"/>
      </material>
    </visual>
    <collision>
      <geometry>
        <mesh filename="package://gazebo_example/meshes/ur10/collision/upperarm.stl"/>
      </geometry>
    </collision>
    <inertial>
      <mass value="12.93"/>
      <origin rpy="0 0 0" xyz="0.0 -0.045 0.306"/>
      <inertia ixx="0.421753803798" ixy="0.0" ixz="0.0" iyy="0.421753803798" iyz="0.0" izz="0.036365625"/>
    </inertial>
  </link>
  <joint name="/mbx/elbow_joint" type="revolute">
    <parent link="/mbx/upper_arm_link"/>
    <child link="/mbx/forearm_link"/>
    <origin rpy="0.0 0.0 0.0" xyz="0.0 -0.1719 0.612"/>
    <axis xyz="0 1 0"/>
    <limit effort="150.0" lower="-3.14159265359" upper="3.14159265359" velocity="3.15"/>
    <dynamics damping="0.0" friction="0.0"/>
  </joint>
  <link name="/mbx/forearm_link">
    <visual>
      <geometry>
        <mesh filename="package://gazebo_example/meshes/ur10/visual/forearm.dae"/>
      </geometry>
      <material name="LightGrey">
        <color rgba="0.7 0.7 0.7 1.0"/>
      </material>
    </visual>
    <collision>
      <geometry>
        <mesh filename="package://gazebo_example/meshes/ur10/collision/forearm.stl"/>
      </geometry>
    </collision>
    <inertial>
      <mass value="3.87"/>
      <origin rpy="0 0 0" xyz="0.0 0.0 0.28615"/>
      <inertia ixx="0.111069694097" ixy="0.0" ixz="0.0" iyy="0.111069694097" iyz="0.0" izz="0.010884375"/>
    </inertial>
  </link>
  <joint name="/mbx/wrist_1_joint" type="revolute">
    <parent link="/mbx/forearm_link"/>
    <child link="/mbx/wrist_1_link"/>
    <origin rpy="0.0 1.57079632679 0.0" xyz="0.0 0.0 0.5723"/>
    <axis xyz="0 1 0"/>
    <limit effort="54.0" lower="-6.28318530718" upper="6.28318530718" velocity="3.2"/>
    <dynamics damping="0.0" friction="0.0"/>
  </joint>
  <link name="/mbx/wrist_1_link">
    <visual>
      <geometry>
        <mesh filename="package://gazebo_example/meshes/ur10/visual/wrist1.dae"/>
      </geometry>
      <material name="LightGrey">
        <color rgba="0.7 0.7 0.7 1.0"/>
      </material>
    </visual>
    <collision>
      <geometry>
        <mesh filename="package://gazebo_example/meshes/ur10/collision/wrist1.stl"/>
      </geometry>
    </collision>
    <inertial>
      <mass value="1.96"/>
      <origin rpy="0 0 0" xyz="0.0 0.1149 0.0"/>
      <inertia ixx="0.0051082479567" ixy="0.0" ixz="0.0" iyy="0.0051082479567" iyz="0.0" izz="0.0055125"/>
    </inertial>
  </link>
  <joint name="/mbx/wrist_2_joint" type="revolute">
    <parent link="/mbx/wrist_1_link"/>
    <child link="/mbx/wrist_2_link"/>
    <origin rpy="0.0 0.0 0.0" xyz="0.0 0.1149 0.0"/>
    <axis xyz="0 0 1"/>
    <limit effort="54.0" lower="-6.28318530718" upper="6.28318530718" velocity="3.2"/>
    <dynamics damping="0.0" friction="0.0"/>
  </joint>
  <link name="/mbx/wrist_2_link">
    <visual>
      <geometry>
        <mesh filename="package://gazebo_example/meshes/ur10/visual/wrist2.dae"/>
      </geometry>
      <material name="LightGrey">
        <color rgba="0.7 0.7 0.7 1.0"/>
      </material>
    </visual>
    <collision>
      <geometry>
        <mesh filename="package://gazebo_example/meshes/ur10/collision/wrist2.stl"/>
      </geometry>
    </collision>
    <inertial>
      <mass value="1.96"/>
      <origin rpy="0 0 0" xyz="0.0 0.0 0.1157"/>
      <inertia ixx="0.0051082479567" ixy="0.0" ixz="0.0" iyy="0.0051082479567" iyz="0.0" izz="0.0055125"/>
    </inertial>
  </link>
  <joint name="/mbx/wrist_3_joint" type="revolute">
    <parent link="/mbx/wrist_2_link"/>
    <child link="/mbx/wrist_3_link"/>
    <origin rpy="0.0 0.0 0.0" xyz="0.0 0.0 0.1157"/>
    <axis xyz="0 1 0"/>
    <limit effort="54.0" lower="-6.28318530718" upper="6.28318530718" velocity="3.2"/>
    <dynamics damping="0.0" friction="0.0"/>
  </joint>
  <link name="/mbx/wrist_3_link">
    <visual>
      <geometry>
        <mesh filename="package://gazebo_example/meshes/ur10/visual/wrist3.dae"/>
      </geometry>
      <material name="LightGrey">
        <color rgba="0.7 0.7 0.7 1.0"/>
      </material>
    </visual>
    <collision>
      <geometry>
        <mesh filename="package://gazebo_example/meshes/ur10/collision/wrist3.stl"/>
      </geometry>
    </collision>
    <inertial>
      <mass value="0.202"/>
      <origin rpy="1.57079632679 0 0" xyz="0.0 0.07695 0.0"/>
      <inertia ixx="0.000117921661165" ixy="0.0" ixz="0.0" iyy="0.000117921661165" iyz="0.0" izz="0.000204525"/>
    </inertial>
  </link>
  <transmission name="/mbx/shoulder_pan_trans">
    <type>transmission_interface/SimpleTransmission</type>
    <joint name="/mbx/shoulder_pan_joint">
      <hardwareInterface>hardware_interface/PositionJointInterface</hardwareInterface>
    </joint>
    <actuator name="/mbx/shoulder_pan_motor">
      <mechanicalReduction>1</mechanicalReduction>
    </actuator>
  </transmission>
  <transmission name="/mbx/shoulder_lift_trans">
    <type>transmission_interface/SimpleTransmission</type>
    <joint name="/mbx/shoulder_lift_joint">
      <hardwareInterface>hardware_interface/PositionJointInterface</hardwareInterface>
    </joint>
    <actuator name="/mbx/shoulder_lift_motor">
      <mechanicalReduction>1</mechanicalReduction>
    </actuator>
  </transmission>
  <transmission name="/mbx/elbow_trans">
    <type>transmission_interface/SimpleTransmission</type>
    <joint name="/mbx/elbow_joint">
      <hardwareInterface>hardware_interface/PositionJointInterface</hardwareInterface>
    </joint>
    <actuator name="/mbx/elbow_motor">
      <mechanicalReduction>1</mechanicalReduction>
    </actuator>
  </transmission>
  <transmission name="/mbx/wrist_1_trans">
    <type>transmission_interface/SimpleTransmission</type>
    <joint name="/mbx/wrist_1_joint">
      <hardwareInterface>hardware_interface/PositionJointInterface</hardwareInterface>
    </joint>
    <actuator name="/mbx/wrist_1_motor">
      <mechanicalReduction>1</mechanicalReduction>
    </actuator>
  </transmission>
  <transmission name="/mbx/wrist_2_trans">
    <type>transmission_interface/SimpleTransmission</type>
    <joint name="/mbx/wrist_2_joint">
      <hardwareInterface>hardware_interface/PositionJointInterface</hardwareInterface>
    </joint>
    <actuator name="/mbx/wrist_2_motor">
      <mechanicalReduction>1</mechanicalReduction>
    </actuator>
  </transmission>
  <transmission name="/mbx/wrist_3_trans">
    <type>transmission_interface/SimpleTransmission</type>
    <joint name="/mbx/wrist_3_joint">
      <hardwareInterface>hardware_interface/PositionJointInterface</hardwareInterface>
    </joint>
    <actuator name="/mbx/wrist_3_motor">
      <mechanicalReduction>1</mechanicalReduction>
    </actuator>
  </transmission>
  <gazebo reference="/mbx/shoulder_link">
    <selfCollide>true</selfCollide>
  </gazebo>
  <gazebo reference="/mbx/upper_arm_link">
    <selfCollide>true</selfCollide>
  </gazebo>
  <gazebo reference="/mbx/forearm_link">
    <selfCollide>true</selfCollide>
  </gazebo>
  <gazebo reference="/mbx/wrist_1_link">
    <selfCollide>true</selfCollide>
  </gazebo>
  <gazebo reference="/mbx/wrist_3_link">
    <selfCollide>true</selfCollide>
  </gazebo>
  <gazebo reference="/mbx/wrist_2_link">
    <selfCollide>true</selfCollide>
  </gazebo>
  <gazebo reference="/mbx/ee_link">
    <selfCollide>true</selfCollide>
  </gazebo>
  <!-- ROS base_link to UR 'Base' Coordinates transform -->
  <link name="/mbx/base"/>
  <joint name="/mbx/base_link-base_fixed_joint" type="fixed">
    <!-- NOTE: this rotation is only needed as long as base_link itself is
                 not corrected wrt the real robot (ie: rotated over 180
                 degrees)
      -->
    <origin rpy="0 0 -3.14159265359" xyz="0 0 0"/>
    <parent link="/mbx/base_link"/>
    <child link="/mbx/base"/>
  </joint>
  <!-- Frame coincident with all-zeros TCP on UR controller -->
  <!--link name="${prefix}tool0"/>
    <joint name="${prefix}wrist_3_link-tool0_fixed_joint" type="fixed">
      <origin xyz="0 ${wrist_3_length} 0" rpy="${pi/-2.0} 0 0"/>
      <parent link="${prefix}wrist_3_link"/>
      <child link="${prefix}tool0"/>
    </joint-->
  <!-- links -->
  <link name="/mbx/car_link">
    <visual>
      <geometry>
        <mesh filename="package://gazebo_example/meshes/carnw.STL"/>
      </geometry>
      <material name="blue"/>
      <origin rpy="1.570796 0 0" xyz="0 0 0"/>
    </visual>
    <collision>
      <geometry>
        <mesh filename="package://gazebo_example/meshes/carnw.STL"/>
      </geometry>
      <origin rpy="1.570796 0 0" xyz="0 0 0"/>
    </collision>
    <inertial>
      <mass value="80.0"/>
      <inertia ixx="1.0" ixy="0.0" ixz="0.0" iyy="1.0" iyz="0.0" izz="1.0"/>
    </inertial>
  </link>
  <!-- gazebo -->
  <gazebo reference="/mbx/car_link">
    <material>Gazebo/SkyBlue</material>
    <mu1>0.5</mu1>
    <mu2>0.5</mu2>
  </gazebo>
  <joint name="/mbx/car2base_link" type="fixed">
    <parent link="/mbx/base"/>
    <child link="/mbx/car_link"/>
    <origin rpy="0 0 3.1415926" xyz="-0.25 0 -0.5"/>
  </joint>
  <link name="/mbx/front_right_wheel">
    <visual>
      <!--<xacro:cylinder_geometry length="${wheel_length}" radius="${wheel_radius}"/>-->
      <geometry>
        <mesh filename="package://gazebo_example/meshes/wheel.STL"/>
      </geometry>
      <origin rpy="1.5707963 1.5707963 0.0" xyz="0.0 0.0 0.0"/>
      <material name="black"/>
    </visual>
    <collision>
      <geometry>
        <!--<xacro:cylinder_geometry length="${wheel_length}" radius="${wheel_radius}"/>-->
        <mesh filename="package://gazebo_example/meshes/wheel.STL"/>
      </geometry>
      <origin rpy="1.5707963 1.5707963 0.0" xyz="0.0 0.0 0.0"/>
    </collision>
    <inertial>
      <mass value="1.0"/>
      <inertia ixx="1.0" ixy="0.0" ixz="0.0" iyy="1.0" iyz="0.0" izz="1.0"/>
    </inertial>
  </link>
  <!-- joints -->
  <joint name="/mbx/front_right_wheel" type="continuous">
    <origin rpy="0.0 0.0 0.0" xyz="0.282 0.275 -0.087"/>
    <parent link="/mbx/car_link"/>
    <child link="/mbx/front_right_wheel"/>
    <axis xyz="0.0 1.0 0.0"/>
  </joint>
  <gazebo reference="/mbx/front_right_wheel">
    <material>Gazebo/Black</material>
    <mu1>0.5</mu1>
    <mu2>0.5</mu2>
  </gazebo>
  <link name="/mbx/front_left_wheel">
    <visual>
      <!--<xacro:cylinder_geometry length="${wheel_length}" radius="${wheel_radius}"/>-->
      <geometry>
        <mesh filename="package://gazebo_example/meshes/wheel.STL"/>
      </geometry>
      <origin rpy="1.5707963 1.5707963 0.0" xyz="0.0 0.0 0.0"/>
      <material name="black"/>
    </visual>
    <collision>
      <geometry>
        <!--<xacro:cylinder_geometry length="${wheel_length}" radius="${wheel_radius}"/>-->
        <mesh filename="package://gazebo_example/meshes/wheel.STL"/>
      </geometry>
      <origin rpy="1.5707963 1.5707963 0.0" xyz="0.0 0.0 0.0"/>
    </collision>
    <inertial>
      <mass value="1.0"/>
      <inertia ixx="1.0" ixy="0.0" ixz="0.0" iyy="1.0" iyz="0.0" izz="1.0"/>
    </inertial>
  </link>
  <!-- joints -->
  <joint name="/mbx/front_left_wheel" type="continuous">
    <origin rpy="0.0 0.0 0.0" xyz="0.282 -0.275 -0.087"/>
    <parent link="/mbx/car_link"/>
    <child link="/mbx/front_left_wheel"/>
    <axis xyz="0.0 1.0 0.0"/>
  </joint>
  <gazebo reference="/mbx/front_left_wheel">
    <material>Gazebo/Black</material>
    <mu1>0.5</mu1>
    <mu2>0.5</mu2>
  </gazebo>
  <link name="/mbx/end_right_wheel">
    <visual>
      <!--<xacro:cylinder_geometry length="${wheel_length}" radius="${wheel_radius}"/>-->
      <geometry>
        <mesh filename="package://gazebo_example/meshes/wheel.STL"/>
      </geometry>
      <origin rpy="1.5707963 1.5707963 0.0" xyz="0.0 0.0 0.0"/>
      <material name="black"/>
    </visual>
    <collision>
      <geometry>
        <!--<xacro:cylinder_geometry length="${wheel_length}" radius="${wheel_radius}"/>-->
        <mesh filename="package://gazebo_example/meshes/wheel.STL"/>
      </geometry>
      <origin rpy="1.5707963 1.5707963 0.0" xyz="0.0 0.0 0.0"/>
    </collision>
    <inertial>
      <mass value="1.0"/>
      <inertia ixx="1.0" ixy="0.0" ixz="0.0" iyy="1.0" iyz="0.0" izz="1.0"/>
    </inertial>
  </link>
  <!-- joints -->
  <joint name="/mbx/end_right_wheel" type="continuous">
    <origin rpy="0.0 0.0 0.0" xyz="-0.282 0.275 -0.087"/>
    <parent link="/mbx/car_link"/>
    <child link="/mbx/end_right_wheel"/>
    <axis xyz="0.0 1.0 0.0"/>
  </joint>
  <gazebo reference="/mbx/end_right_wheel">
    <material>Gazebo/Black</material>
    <mu1>0.5</mu1>
    <mu2>0.5</mu2>
  </gazebo>
  <link name="/mbx/end_left_wheel">
    <visual>
      <!--<xacro:cylinder_geometry length="${wheel_length}" radius="${wheel_radius}"/>-->
      <geometry>
        <mesh filename="package://gazebo_example/meshes/wheel.STL"/>
      </geometry>
      <origin rpy="1.5707963 1.5707963 0.0" xyz="0.0 0.0 0.0"/>
      <material name="black"/>
    </visual>
    <collision>
      <geometry>
        <!--<xacro:cylinder_geometry length="${wheel_length}" radius="${wheel_radius}"/>-->
        <mesh filename="package://gazebo_example/meshes/wheel.STL"/>
      </geometry>
      <origin rpy="1.5707963 1.5707963 0.0" xyz="0.0 0.0 0.0"/>
    </collision>
    <inertial>
      <mass value="1.0"/>
      <inertia ixx="1.0" ixy="0.0" ixz="0.0" iyy="1.0" iyz="0.0" izz="1.0"/>
    </inertial>
  </link>
  <!-- joints -->
  <joint name="/mbx/end_left_wheel" type="continuous">
    <origin rpy="0.0 0.0 0.0" xyz="-0.282 -0.275 -0.087"/>
    <parent link="/mbx/car_link"/>
    <child link="/mbx/end_left_wheel"/>
    <axis xyz="0.0 1.0 0.0"/>
  </joint>
  <gazebo reference="/mbx/end_left_wheel">
    <material>Gazebo/Black</material>
    <mu1>0.5</mu1>
    <mu2>0.5</mu2>
  </gazebo>
  <transmission name="/mbx/front_right_wheel_transmission">
    <type>transmission_interface/SimpleTransmission</type>
    <joint name="/mbx/front_right_wheel">
      <hardwareInterface>hardware_interface/EffortJointInterface</hardwareInterface>
    </joint>
    <actuator name="/mbx/front_right_wheel_motor">
      <mechanicalReducction>1</mechanicalReducction>
    </actuator>
  </transmission>
  <transmission name="/mbx/front_left_wheel_transmission">
    <type>transmission_interface/SimpleTransmission</type>
    <joint name="/mbx/front_left_wheel">
      <hardwareInterface>hardware_interface/EffortJointInterface</hardwareInterface>
    </joint>
    <actuator name="/mbx/front_left_wheel_motor">
      <mechanicalReducction>1</mechanicalReducction>
    </actuator>
  </transmission>
  <transmission name="/mbx/end_right_wheel_transmission">
    <type>transmission_interface/SimpleTransmission</type>
    <joint name="/mbx/end_right_wheel">
      <hardwareInterface>hardware_interface/EffortJointInterface</hardwareInterface>
    </joint>
    <actuator name="/mbx/end_right_wheel_motor">
      <mechanicalReducction>1</mechanicalReducction>
    </actuator>
  </transmission>
  <transmission name="/mbx/end_left_wheel_transmission">
    <type>transmission_interface/SimpleTransmission</type>
    <joint name="/mbx/end_left_wheel">
      <hardwareInterface>hardware_interface/EffortJointInterface</hardwareInterface>
    </joint>
    <actuator name="/mbx/end_left_wheel_motor">
      <mechanicalReducction>1</mechanicalReducction>
    </actuator>
  </transmission>
  <link name="/mbx/front_right_wheel2">
    <visual>
      <!--<xacro:cylinder_geometry length="${wheel_length}" radius="${wheel_radius}"/>-->
      <geometry>
        <mesh filename="package://gazebo_example/meshes/wheel.STL"/>
      </geometry>
      <origin rpy="1.5707963 1.5707963 0.0" xyz="0.0 0.0 0.0"/>
      <material name="black"/>
    </visual>
    <collision>
      <geometry>
        <!--<xacro:cylinder_geometry length="${wheel_length}" radius="${wheel_radius}"/>-->
        <mesh filename="package://gazebo_example/meshes/wheel.STL"/>
      </geometry>
      <origin rpy="1.5707963 1.5707963 0.0" xyz="0.0 0.0 0.0"/>
    </collision>
    <inertial>
      <mass value="1.0"/>
      <inertia ixx="1.0" ixy="0.0" ixz="0.0" iyy="1.0" iyz="0.0" izz="1.0"/>
    </inertial>
  </link>
  <!-- joints -->
  <joint name="/mbx/front_right_wheel2" type="fixed">
    <origin rpy="0.0 0.0 0.0" xyz="0.083 0.275 -0.087"/>
    <parent link="/mbx/car_link"/>
    <child link="/mbx/front_right_wheel2"/>
    <!--axis xyz="0.0 1.0 0.0"/-->
  </joint>
  <gazebo reference="/mbx/front_right_wheel2">
    <material>Gazebo/Black</material>
    <mu1>0.5</mu1>
    <mu2>0.5</mu2>
  </gazebo>
  <link name="/mbx/front_left_wheel2">
    <visual>
      <!--<xacro:cylinder_geometry length="${wheel_length}" radius="${wheel_radius}"/>-->
      <geometry>
        <mesh filename="package://gazebo_example/meshes/wheel.STL"/>
      </geometry>
      <origin rpy="1.5707963 1.5707963 0.0" xyz="0.0 0.0 0.0"/>
      <material name="black"/>
    </visual>
    <collision>
      <geometry>
        <!--<xacro:cylinder_geometry length="${wheel_length}" radius="${wheel_radius}"/>-->
        <mesh filename="package://gazebo_example/meshes/wheel.STL"/>
      </geometry>
      <origin rpy="1.5707963 1.5707963 0.0" xyz="0.0 0.0 0.0"/>
    </collision>
    <inertial>
      <mass value="1.0"/>
      <inertia ixx="1.0" ixy="0.0" ixz="0.0" iyy="1.0" iyz="0.0" izz="1.0"/>
    </inertial>
  </link>
  <!-- joints -->
  <joint name="/mbx/front_left_wheel2" type="fixed">
    <origin rpy="0.0 0.0 0.0" xyz="0.083 -0.275 -0.087"/>
    <parent link="/mbx/car_link"/>
    <child link="/mbx/front_left_wheel2"/>
    <!--axis xyz="0.0 1.0 0.0"/-->
  </joint>
  <gazebo reference="/mbx/front_left_wheel2">
    <material>Gazebo/Black</material>
    <mu1>0.5</mu1>
    <mu2>0.5</mu2>
  </gazebo>
  <link name="/mbx/end_right_wheel2">
    <visual>
      <!--<xacro:cylinder_geometry length="${wheel_length}" radius="${wheel_radius}"/>-->
      <geometry>
        <mesh filename="package://gazebo_example/meshes/wheel.STL"/>
      </geometry>
      <origin rpy="1.5707963 1.5707963 0.0" xyz="0.0 0.0 0.0"/>
      <material name="black"/>
    </visual>
    <collision>
      <geometry>
        <!--<xacro:cylinder_geometry length="${wheel_length}" radius="${wheel_radius}"/>-->
        <mesh filename="package://gazebo_example/meshes/wheel.STL"/>
      </geometry>
      <origin rpy="1.5707963 1.5707963 0.0" xyz="0.0 0.0 0.0"/>
    </collision>
    <inertial>
      <mass value="1.0"/>
      <inertia ixx="1.0" ixy="0.0" ixz="0.0" iyy="1.0" iyz="0.0" izz="1.0"/>
    </inertial>
  </link>
  <!-- joints -->
  <joint name="/mbx/end_right_wheel2" type="fixed">
    <origin rpy="0.0 0.0 0.0" xyz="-0.083 0.275 -0.087"/>
    <parent link="/mbx/car_link"/>
    <child link="/mbx/end_right_wheel2"/>
    <!--axis xyz="0.0 1.0 0.0"/-->
  </joint>
  <gazebo reference="/mbx/end_right_wheel2">
    <material>Gazebo/Black</material>
    <mu1>0.5</mu1>
    <mu2>0.5</mu2>
  </gazebo>
  <link name="/mbx/end_left_wheel2">
    <visual>
      <!--<xacro:cylinder_geometry length="${wheel_length}" radius="${wheel_radius}"/>-->
      <geometry>
        <mesh filename="package://gazebo_example/meshes/wheel.STL"/>
      </geometry>
      <origin rpy="1.5707963 1.5707963 0.0" xyz="0.0 0.0 0.0"/>
      <material name="black"/>
    </visual>
    <collision>
      <geometry>
        <!--<xacro:cylinder_geometry length="${wheel_length}" radius="${wheel_radius}"/>-->
        <mesh filename="package://gazebo_example/meshes/wheel.STL"/>
      </geometry>
      <origin rpy="1.5707963 1.5707963 0.0" xyz="0.0 0.0 0.0"/>
    </collision>
    <inertial>
      <mass value="1.0"/>
      <inertia ixx="1.0" ixy="0.0" ixz="0.0" iyy="1.0" iyz="0.0" izz="1.0"/>
    </inertial>
  </link>
  <!-- joints -->
  <joint name="/mbx/end_left_wheel2" type="fixed">
    <origin rpy="0.0 0.0 0.0" xyz="-0.083 -0.275 -0.087"/>
    <parent link="/mbx/car_link"/>
    <child link="/mbx/end_left_wheel2"/>
    <!--axis xyz="0.0 1.0 0.0"/-->
  </joint>
  <gazebo reference="/mbx/end_left_wheel2">
    <material>Gazebo/Black</material>
    <mu1>0.5</mu1>
    <mu2>0.5</mu2>
  </gazebo>
  <!--here we will start the commenting links:
        1. base_0
        2. base
        3. platform_support
        4. platform
    -->
  <!-- start commenting 1 here-->
  <!--joint name="${ns}car2base_0" type = "fixed">
		<parent link ="${ns}car_link"/>
		<child link = "${ns}base_0"/>
		<origin rpy =" 0 0.785398 0" xyz = "0.03 0 0.34"/>
	</joint>
	<link name="${ns}base_0">
		<visual>
			<geometry>
				<box size="0.01 0.01 0.01" />
     		</geometry>
        	<material name="a">
				<color rgba="0.2 0 0 1"/>
			</material>	
			<origin rpy="0 0 0" xyz="0 0 0"/>
    	</visual>
	</link>
	<joint name="${ns}car2base" type = "fixed">
		<parent link ="${ns}base_0"/>
		<child link = "${ns}base"/>
		<origin rpy =" 0 0 0.523599" xyz = "0 0 0"/>
	</joint>


    <link name="${ns}base">
        <visual>
            <geometry>
                <mesh filename="package://gazebo_example/meshes/base_link.STL" />
            </geometry>
            <origin rpy="1.570796 0 0" xyz="0 0 0"/>
            <material name="white"/>
        </visual>
        <collision>
            <geometry>
                <mesh filename="package://gazebo_example/meshes/base_link.STL" />
            </geometry>
            <origin rpy="1.570796 0 0" xyz="0 0 0"/>
        </collision>
        <xacro:default_inertial mass="0.6"/>
    </link>
    <gazebo reference="${ns}base">
        <material>Gazebo/Red</material>
        <mu1>0.5</mu1>
        <mu2>0.5</mu2>
    </gazebo-->
  <!--end commenting 1 here-->
  <!--comment all the base_connectball_joint macro-->
  <!--start commenting
    <xacro:base_connectball_joint chain_num="1" n1="0.0" n2="0.14" n3="0.0" n4="0.04007" n5="-0.206142" n6="0.06393"/>
    <xacro:base_connectball_joint chain_num="2" n1="0.0" n2="-0.13" n3="0.0" n4="-0.04007" n5="-0.206142" n6="0.06393"/>
    <xacro:base_connectball_joint chain_num="3" n1="0.0" n2="-0.13" n3="0.0" n4="0.198559" n5="0.068369" n6="0.06393"/>
    <xacro:base_connectball_joint chain_num="4" n1="0.0" n2="-0.28" n3="0.0" n4="0.158489" n5="0.137772" n6="0.06393"/>
    <xacro:base_connectball_joint chain_num="5" n1="0.0" n2="0.14" n3="0.0" n4="-0.198559" n5="0.068369" n6="0.06393"/>
    <xacro:base_connectball_joint chain_num="6" n1="0.0" n2="0.28" n3="0.0" n4="-0.158489" n5="0.137772" n6="0.06393"/>
    -->
  <!--comment all the connectball_chain_joint macro-->
  <!--start commenting
    <xacro:connectball_chain_joint chain_num="1" n1="-0.22" n2="0.0" n3="0.0" n4="0.0" n5="0.0" n6="0.0"/>
    <xacro:connectball_chain_joint chain_num="2" n1="-0.22" n2="0.0" n3="0.0" n4="0.0" n5="0.0" n6="0.0"/>
    <xacro:connectball_chain_joint chain_num="3" n1="0.25" n2="0.0" n3="0.0" n4="0.0" n5="0.0" n6="0.0"/>
    <xacro:connectball_chain_joint chain_num="4" n1="-0.01" n2="0.0" n3="0.0" n4="0.0" n5="0.0" n6="0.0"/>
    <xacro:connectball_chain_joint chain_num="5" n1="0.26" n2="0.0" n3="0.0" n4="0.0" n5="0.0" n6="0.0"/>
    <xacro:connectball_chain_joint chain_num="6" n1="-0.01" n2="0.0" n3="0.0" n4="0.0" n5="0.0" n6="0.0"/>
    -->
  <!--comment all the chain_chain_joint macro-->
  <!--start commenting
    <xacro:chain_chain_joint chain_num="1" n1="0.0" n2="0.0" n3="2.5827825" n4="0.0" n5="0.0" n6="0.2"/>
    <xacro:chain_chain_joint chain_num="2" n1="0.0" n2="0.0" n3="0.67881" n4="0.0" n5="0.0" n6="0.2"/>
    <xacro:chain_chain_joint chain_num="3" n1="0.0" n2="0.0" n3="2.5673205" n4="0.0" n5="0.0" n6="0.2"/>
    <xacro:chain_chain_joint chain_num="4" n1="0.0" n2="0.0" n3="4.7671776" n4="0.0" n5="0.0" n6="0.2"/>
    <xacro:chain_chain_joint chain_num="5" n1="0.0" n2="0.0" n3="6.951573" n4="0.0" n5="0.0" n6="0.2"/>
    <xacro:chain_chain_joint chain_num="6" n1="0.0" n2="0.0" n3="4.6476" n4="0.0" n5="0.0" n6="0.2"/>
    -->
  <!--start commenting 2 here-->
  <!--joint name="${ns}platform_support2base" type = "fixed">
		<parent link ="${ns}base"/>
		<child link = "${ns}platform_support"/>
		<origin rpy ="0 0 0" xyz = "0 0 0.217"/>
	</joint>
	<link name="${ns}platform_support">
        <visual>
            <xacro:box_geometry length="0.02" width="0.02" height="0.434"/>
            <origin rpy="0 0 0" xyz="0 0 0"/>
            <material name="red"/>
        </visual>
        <collision>
            <xacro:box_geometry length="0.02" width="0.02" height="0.434"/>
            <origin rpy="0 0 0" xyz="0 0 0"/>
        </collision>
        <xacro:default_inertial mass="0.01"/>
	</link>
	<joint name="${ns}support2platform" type = "fixed"> 
		<parent link ="${ns}platform_support"/>
		<child link = "${ns}platform"/>
		<origin rpy ="0 0 0" xyz = "0 0 0.25"/>
	</joint>
	<link name="${ns}platform">
        <visual>
            <geometry>
                <mesh filename="package://gazebo_example/meshes/platform.STL" />
            </geometry>
            <origin rpy="-1.570796 0 0" xyz="0 0 0"/>
            <material name="red"/>
        </visual>
        <collision>
            <geometry>
                <mesh filename="package://gazebo_example/meshes/platform.STL" />
            </geometry>
            <origin rpy="-1.570796 0 0" xyz="0 0 0"/>
        </collision>
        <xacro:default_inertial mass="0.05"/>
	</link>
    <gazebo reference="${ns}platform">
        <material>Gazebo/Green</material>
        <mu1>0.5</mu1>
        <mu2>0.5</mu2>
    </gazebo>
	<joint name="${ns}platform2connect" type = "continuous"> 
		<parent link ="${ns}platform"/>
		<child link = "${ns}connect"/>
		<origin rpy ="0 0 0" xyz = "0 0 0"/>
		<axis xyz="0 0 1"/>
	</joint-->
  <!--end commenting 2 here-->
  <!--
	<link name="${ns}connect">
        <visual>
            <geometry>
                <mesh filename="package://gazebo_example/meshes/connect2mz.STL" />
            </geometry>
            <origin rpy="1.570796 0 0" xyz="0 0 0"/>
            <material name="red"/>
        </visual>
        <collision>
            <geometry>
                <mesh filename="package://gazebo_example/meshes/connect2mz.STL" />
            </geometry>
            <origin rpy="1.570796 0 0" xyz="0 0 0"/>
        </collision>
        <xacro:default_inertial mass="0.01"/>
	</link>
    <gazebo reference="${ns}connect">
        <material>Gazebo/Black</material>
        <mu1>0.5</mu1>
        <mu2>0.5</mu2>
    </gazebo>
    -->
  <!-- ros_control plugin -->
  <gazebo>
    <plugin filename="libgazebo_ros_control.so" name="gazebo_ros_control">
      <robotNamespace>/mbx</robotNamespace>
      <robotParam>/mbx/robot_description</robotParam>
      <robotSimType>gazebo_ros_control/DefaultRobotHWSim</robotSimType>
    </plugin>
  </gazebo>
  <!--move_base plugin -->
  <gazebo>
    <plugin filename="libgazebo_ros_planar_move.so" name="base_controller">
      <commandTopic>cmd_vel</commandTopic>
      <odometryTopic>world</odometryTopic>
      <odometryFrame>world</odometryFrame>
      <odometryRate>20.0</odometryRate>
      <robotBaseFrame>/mbx/base_link</robotBaseFrame>
    </plugin>
  </gazebo>
</robot>
